You're accessing the development server over HTTPS, but it only supports HTTP.
Internal Server Error: /api/token/
Traceback (most recent call last):
  File "/home/jp/.local/lib/python3.10/site-packages/django/core/handlers/exception.py", line 55, in inner
    response = get_response(request)
  File "/home/jp/.local/lib/python3.10/site-packages/django/core/handlers/base.py", line 197, in _get_response
    response = wrapped_callback(request, *callback_args, **callback_kwargs)
  File "/home/jp/.local/lib/python3.10/site-packages/django/views/decorators/csrf.py", line 65, in _view_wrapper
    return view_func(request, *args, **kwargs)
  File "/home/jp/.local/lib/python3.10/site-packages/django/views/generic/base.py", line 104, in view
    return self.dispatch(request, *args, **kwargs)
  File "/home/jp/.local/lib/python3.10/site-packages/rest_framework/views.py", line 515, in dispatch
    response = self.handle_exception(exc)
  File "/home/jp/.local/lib/python3.10/site-packages/rest_framework/views.py", line 475, in handle_exception
    self.raise_uncaught_exception(exc)
  File "/home/jp/.local/lib/python3.10/site-packages/rest_framework/views.py", line 486, in raise_uncaught_exception
    raise exc
  File "/home/jp/.local/lib/python3.10/site-packages/rest_framework/views.py", line 512, in dispatch
    response = handler(request, *args, **kwargs)
  File "/home/jp/.local/lib/python3.10/site-packages/rest_framework_simplejwt/views.py", line 44, in post
    serializer.is_valid(raise_exception=True)
  File "/home/jp/.local/lib/python3.10/site-packages/rest_framework/serializers.py", line 225, in is_valid
    self._validated_data = self.run_validation(self.initial_data)
  File "/home/jp/.local/lib/python3.10/site-packages/rest_framework/serializers.py", line 447, in run_validation
    value = self.validate(value)
  File "/home/jp/.local/lib/python3.10/site-packages/rest_framework_simplejwt/serializers.py", line 73, in validate
    data = super().validate(attrs)
  File "/home/jp/.local/lib/python3.10/site-packages/rest_framework_simplejwt/serializers.py", line 54, in validate
    self.user = authenticate(**authenticate_kwargs)
  File "/home/jp/.local/lib/python3.10/site-packages/django/views/decorators/debug.py", line 75, in sensitive_variables_wrapper
    return func(*func_args, **func_kwargs)
  File "/home/jp/.local/lib/python3.10/site-packages/django/contrib/auth/__init__.py", line 114, in authenticate
    user = backend.authenticate(request, **credentials)
  File "/home/jp/Desktop/projinteg_github/StockControl/stock_control_webservices/inventory/backends.py", line 10, in authenticate
    user = User.objects.get(email=username)
  File "/home/jp/.local/lib/python3.10/site-packages/django/db/models/manager.py", line 87, in manager_method
    return getattr(self.get_queryset(), name)(*args, **kwargs)
  File "/home/jp/.local/lib/python3.10/site-packages/django/db/models/query.py", line 636, in get
    raise self.model.MultipleObjectsReturned(
django.contrib.auth.models.User.MultipleObjectsReturned: get() returned more than one User -- it returned 2!
"POST /api/token/ HTTP/1.1" 500 134718
Internal Server Error: /api/token/
Traceback (most recent call last):
  File "/home/jp/.local/lib/python3.10/site-packages/django/core/handlers/exception.py", line 55, in inner
    response = get_response(request)
  File "/home/jp/.local/lib/python3.10/site-packages/django/core/handlers/base.py", line 197, in _get_response
    response = wrapped_callback(request, *callback_args, **callback_kwargs)
  File "/home/jp/.local/lib/python3.10/site-packages/django/views/decorators/csrf.py", line 65, in _view_wrapper
    return view_func(request, *args, **kwargs)
  File "/home/jp/.local/lib/python3.10/site-packages/django/views/generic/base.py", line 104, in view
    return self.dispatch(request, *args, **kwargs)
  File "/home/jp/.local/lib/python3.10/site-packages/rest_framework/views.py", line 515, in dispatch
    response = self.handle_exception(exc)
  File "/home/jp/.local/lib/python3.10/site-packages/rest_framework/views.py", line 475, in handle_exception
    self.raise_uncaught_exception(exc)
  File "/home/jp/.local/lib/python3.10/site-packages/rest_framework/views.py", line 486, in raise_uncaught_exception
    raise exc
  File "/home/jp/.local/lib/python3.10/site-packages/rest_framework/views.py", line 512, in dispatch
    response = handler(request, *args, **kwargs)
  File "/home/jp/.local/lib/python3.10/site-packages/rest_framework_simplejwt/views.py", line 44, in post
    serializer.is_valid(raise_exception=True)
  File "/home/jp/.local/lib/python3.10/site-packages/rest_framework/serializers.py", line 225, in is_valid
    self._validated_data = self.run_validation(self.initial_data)
  File "/home/jp/.local/lib/python3.10/site-packages/rest_framework/serializers.py", line 447, in run_validation
    value = self.validate(value)
  File "/home/jp/.local/lib/python3.10/site-packages/rest_framework_simplejwt/serializers.py", line 73, in validate
    data = super().validate(attrs)
  File "/home/jp/.local/lib/python3.10/site-packages/rest_framework_simplejwt/serializers.py", line 54, in validate
    self.user = authenticate(**authenticate_kwargs)
  File "/home/jp/.local/lib/python3.10/site-packages/django/views/decorators/debug.py", line 75, in sensitive_variables_wrapper
    return func(*func_args, **func_kwargs)
  File "/home/jp/.local/lib/python3.10/site-packages/django/contrib/auth/__init__.py", line 114, in authenticate
    user = backend.authenticate(request, **credentials)
  File "/home/jp/Desktop/projinteg_github/StockControl/stock_control_webservices/inventory/backends.py", line 10, in authenticate
    user = User.objects.get(email=username)
  File "/home/jp/.local/lib/python3.10/site-packages/django/db/models/manager.py", line 87, in manager_method
    return getattr(self.get_queryset(), name)(*args, **kwargs)
  File "/home/jp/.local/lib/python3.10/site-packages/django/db/models/query.py", line 636, in get
    raise self.model.MultipleObjectsReturned(
django.contrib.auth.models.User.MultipleObjectsReturned: get() returned more than one User -- it returned 2!
"POST /api/token/ HTTP/1.1" 500 134718
Internal Server Error: /api/v1/itens/
Traceback (most recent call last):
  File "/home/jp/.local/lib/python3.10/site-packages/django/db/backends/utils.py", line 105, in _execute
    return self.cursor.execute(sql, params)
psycopg2.errors.InvalidTextRepresentation: invalid input syntax for type bigint: "TEST_ITEM2"
LINE 1: ...od_sku", "descricao_item", "unid_medida") VALUES ('TEST_ITEM...
                                                             ^


The above exception was the direct cause of the following exception:

Traceback (most recent call last):
  File "/home/jp/.local/lib/python3.10/site-packages/django/core/handlers/exception.py", line 55, in inner
    response = get_response(request)
  File "/home/jp/.local/lib/python3.10/site-packages/django/core/handlers/base.py", line 197, in _get_response
    response = wrapped_callback(request, *callback_args, **callback_kwargs)
  File "/home/jp/.local/lib/python3.10/site-packages/django/views/decorators/csrf.py", line 65, in _view_wrapper
    return view_func(request, *args, **kwargs)
  File "/home/jp/.local/lib/python3.10/site-packages/rest_framework/viewsets.py", line 125, in view
    return self.dispatch(request, *args, **kwargs)
  File "/home/jp/.local/lib/python3.10/site-packages/rest_framework/views.py", line 515, in dispatch
    response = self.handle_exception(exc)
  File "/home/jp/.local/lib/python3.10/site-packages/rest_framework/views.py", line 475, in handle_exception
    self.raise_uncaught_exception(exc)
  File "/home/jp/.local/lib/python3.10/site-packages/rest_framework/views.py", line 486, in raise_uncaught_exception
    raise exc
  File "/home/jp/.local/lib/python3.10/site-packages/rest_framework/views.py", line 512, in dispatch
    response = handler(request, *args, **kwargs)
  File "/home/jp/.local/lib/python3.10/site-packages/rest_framework/mixins.py", line 19, in create
    self.perform_create(serializer)
  File "/home/jp/.local/lib/python3.10/site-packages/rest_framework/mixins.py", line 24, in perform_create
    serializer.save()
  File "/home/jp/.local/lib/python3.10/site-packages/rest_framework/serializers.py", line 210, in save
    self.instance = self.create(validated_data)
  File "/home/jp/.local/lib/python3.10/site-packages/rest_framework/serializers.py", line 991, in create
    instance = ModelClass._default_manager.create(**validated_data)
  File "/home/jp/.local/lib/python3.10/site-packages/django/db/models/manager.py", line 87, in manager_method
    return getattr(self.get_queryset(), name)(*args, **kwargs)
  File "/home/jp/.local/lib/python3.10/site-packages/django/db/models/query.py", line 663, in create
    obj.save(force_insert=True, using=self.db)
  File "/home/jp/.local/lib/python3.10/site-packages/django/db/models/base.py", line 902, in save
    self.save_base(
  File "/home/jp/.local/lib/python3.10/site-packages/django/db/models/base.py", line 1008, in save_base
    updated = self._save_table(
  File "/home/jp/.local/lib/python3.10/site-packages/django/db/models/base.py", line 1169, in _save_table
    results = self._do_insert(
  File "/home/jp/.local/lib/python3.10/site-packages/django/db/models/base.py", line 1210, in _do_insert
    return manager._insert(
  File "/home/jp/.local/lib/python3.10/site-packages/django/db/models/manager.py", line 87, in manager_method
    return getattr(self.get_queryset(), name)(*args, **kwargs)
  File "/home/jp/.local/lib/python3.10/site-packages/django/db/models/query.py", line 1854, in _insert
    return query.get_compiler(using=using).execute_sql(returning_fields)
  File "/home/jp/.local/lib/python3.10/site-packages/django/db/models/sql/compiler.py", line 1881, in execute_sql
    cursor.execute(sql, params)
  File "/home/jp/.local/lib/python3.10/site-packages/django/db/backends/utils.py", line 122, in execute
    return super().execute(sql, params)
  File "/home/jp/.local/lib/python3.10/site-packages/django/db/backends/utils.py", line 79, in execute
    return self._execute_with_wrappers(
  File "/home/jp/.local/lib/python3.10/site-packages/django/db/backends/utils.py", line 92, in _execute_with_wrappers
    return executor(sql, params, many, context)
  File "/home/jp/.local/lib/python3.10/site-packages/django/db/backends/utils.py", line 100, in _execute
    with self.db.wrap_database_errors:
  File "/home/jp/.local/lib/python3.10/site-packages/django/db/utils.py", line 91, in __exit__
    raise dj_exc_value.with_traceback(traceback) from exc_value
  File "/home/jp/.local/lib/python3.10/site-packages/django/db/backends/utils.py", line 105, in _execute
    return self.cursor.execute(sql, params)
django.db.utils.DataError: invalid input syntax for type bigint: "TEST_ITEM2"
LINE 1: ...od_sku", "descricao_item", "unid_medida") VALUES ('TEST_ITEM...
                                                             ^

"POST /api/v1/itens/ HTTP/1.1" 500 196014
